![image](https://user-images.githubusercontent.com/89120960/228775234-7f445589-879d-4dcc-8acc-bd9999854533.png)








<h1>Here is line by line execution of code</h1>
<h2>Sure! Here's a line-by-line explanation of the execution of the code:</h2>
<div></h2>
async function FetchFunct(ApiUrl){
This line declares an asynchronous function called FetchFunct that takes a single parameter ApiUrl.</h2>
</div>

<div><h2>
const response = await fetch(ApiUrl).catch(()=>{
    throw new Error('Network Error')
  })</h2>
</div>
<p>This line uses the fetch API to make a network request to the URL specified by the ApiUrl parameter. The await keyword is used to wait for the request to complete and return a response object. If there is an error in making the network request, the catch block will throw a new error object with the message "Network Error".</p>

<div><h2>
if (response){
    if(response.ok){
        const data = await response.json().catch(()=>{
            throw new Error('Unexpected.Error')
        })</h2>
</div>
<p>This block of code checks if the response object exists and checks if the response object is OK (status code 200-299). If the response is OK, the json() method is used to parse the response body as JSON and store it in a data variable. If there is an error parsing the response body, the catch block will throw a new error object with the message "Unexpected.Error".</p>


![image](https://user-images.githubusercontent.com/89120960/228777729-cf9683d2-db00-4e44-a7a9-3a5f713f1a36.png)

![image](https://user-images.githubusercontent.com/89120960/228777951-995d5643-ec73-4049-83d9-ab08b052029c.png)

![image](https://user-images.githubusercontent.com/89120960/228778108-b702faef-2b0a-49ad-88a5-0e368e90d337.png)

![image](https://user-images.githubusercontent.com/89120960/228778234-24d0f297-5a67-4b73-9c64-2b13a80c0777.png)




<div><h2>
if(data){
    return data
}
  </h2>
</div>
<p>If the data variable is truthy (i.e., it exists and is not null, undefined, or false), it is returned from the function using the return keyword.</p>

<div><h2>
else{
    throw new Error(response.statusText)
}
  </h2>
</div>
<p>If the response object is not OK, the function throws a new error object with the status text of the response object.</p>

<div><h2>
Const url = 'dummyUrl'
FetchFunct(url)
  .then((data)=>{
    console.log(data)
  })
  .catch((err)=>{
    console.log(err.message)
  })</h2>
</div>
<p>These lines declare a url variable with the value of 'dummyUrl'. The FetchFunct function is called with this URL as an argument. If the function call succeeds and returns a value, the then method is called with the data value and logs it to the console. If the function call fails and throws an error, the catch method is called with the error object and logs its message property to the console.</p>

